Traceback (most recent call last):
  File "/home/nelo/miniconda3/lib/python3.11/site-packages/jupyter_cache/executors/utils.py", line 58, in single_nb_execution
    executenb(
  File "/home/nelo/miniconda3/lib/python3.11/site-packages/nbclient/client.py", line 1305, in execute
    return NotebookClient(nb=nb, resources=resources, km=km, **kwargs).execute()
           ^^^^^^^^^^^^^^^^^^^^^^^^^^^^^^^^^^^^^^^^^^^^^^^^^^^^^^^^^^^^^^^^^^^^^
  File "/home/nelo/miniconda3/lib/python3.11/site-packages/jupyter_core/utils/__init__.py", line 166, in wrapped
    return loop.run_until_complete(inner)
           ^^^^^^^^^^^^^^^^^^^^^^^^^^^^^^
  File "/home/nelo/miniconda3/lib/python3.11/asyncio/base_events.py", line 653, in run_until_complete
    return future.result()
           ^^^^^^^^^^^^^^^
  File "/home/nelo/miniconda3/lib/python3.11/site-packages/nbclient/client.py", line 705, in async_execute
    await self.async_execute_cell(
  File "/home/nelo/miniconda3/lib/python3.11/site-packages/nbclient/client.py", line 1058, in async_execute_cell
    await self._check_raise_for_error(cell, cell_index, exec_reply)
  File "/home/nelo/miniconda3/lib/python3.11/site-packages/nbclient/client.py", line 914, in _check_raise_for_error
    raise CellExecutionError.from_cell_and_msg(cell, exec_reply_content)
nbclient.exceptions.CellExecutionError: An error occurred while executing the following cell:
------------------
from regression import calculate_error, get_train_test_validation
from sklearn.ensemble import RandomForestRegressor

X_train, X_test, X_val, y_train, y_test, y_val = get_train_test_validation()


reg = RandomForestRegressor()
reg.fit(X_train, y_train)
y_pred = reg.predict(X_val)

calculate_error(y_pred, y_val)

------------------


[0;31m---------------------------------------------------------------------------[0m
[0;31mTypeError[0m                                 Traceback (most recent call last)
Cell [0;32mIn[2], line 11[0m
[1;32m      8[0m reg[38;5;241m.[39mfit(X_train, y_train)
[1;32m      9[0m y_pred [38;5;241m=[39m reg[38;5;241m.[39mpredict(X_val)
[0;32m---> 11[0m [43mcalculate_error[49m[43m([49m[43my_pred[49m[43m,[49m[43m [49m[43my_val[49m[43m)[49m

File [0;32m/mnt/Datos/proyectos/Especialidad BigDataIA/repositorios/sistemas_aprendizaje_automatico/apuntes_web/markdowns/sistemas_supervisados/regresion/modelos/../../../../code/regression.py:13[0m, in [0;36mcalculate_error[0;34m(y_val, y_pred)[0m
[1;32m     11[0m [38;5;28;01mdef[39;00m [38;5;21mcalculate_error[39m(y_val, y_pred):
[1;32m     12[0m     [38;5;66;03m#calcular RMSE[39;00m
[0;32m---> 13[0m     rmse [38;5;241m=[39m [43mmean_absolute_error[49m[43m([49m[43my_val[49m[43m,[49m[43m [49m[43my_pred[49m[43m,[49m[43m [49m[43msquared[49m[38;5;241;43m=[39;49m[38;5;28;43;01mFalse[39;49;00m[43m)[49m
[1;32m     14[0m     [38;5;28mprint[39m([38;5;124m"[39m[38;5;124mMAE: [39m[38;5;124m"[39m [38;5;241m+[39m [38;5;28mstr[39m([38;5;28mround[39m(rmse, [38;5;241m2[39m)))
[1;32m     16[0m     mape [38;5;241m=[39m mean_absolute_percentage_error(y_val, y_pred)

File [0;32m~/miniconda3/lib/python3.11/site-packages/sklearn/utils/_param_validation.py:189[0m, in [0;36mvalidate_params.<locals>.decorator.<locals>.wrapper[0;34m(*args, **kwargs)[0m
[1;32m    186[0m func_sig [38;5;241m=[39m signature(func)
[1;32m    188[0m [38;5;66;03m# Map *args/**kwargs to the function signature[39;00m
[0;32m--> 189[0m params [38;5;241m=[39m [43mfunc_sig[49m[38;5;241;43m.[39;49m[43mbind[49m[43m([49m[38;5;241;43m*[39;49m[43margs[49m[43m,[49m[43m [49m[38;5;241;43m*[39;49m[38;5;241;43m*[39;49m[43mkwargs[49m[43m)[49m
[1;32m    190[0m params[38;5;241m.[39mapply_defaults()
[1;32m    192[0m [38;5;66;03m# ignore self/cls and positional/keyword markers[39;00m

File [0;32m~/miniconda3/lib/python3.11/inspect.py:3212[0m, in [0;36mSignature.bind[0;34m(self, *args, **kwargs)[0m
[1;32m   3207[0m [38;5;28;01mdef[39;00m [38;5;21mbind[39m([38;5;28mself[39m, [38;5;241m/[39m, [38;5;241m*[39margs, [38;5;241m*[39m[38;5;241m*[39mkwargs):
[1;32m   3208[0m [38;5;250m    [39m[38;5;124;03m"""Get a BoundArguments object, that maps the passed `args`[39;00m
[1;32m   3209[0m [38;5;124;03m    and `kwargs` to the function's signature.  Raises `TypeError`[39;00m
[1;32m   3210[0m [38;5;124;03m    if the passed arguments can not be bound.[39;00m
[1;32m   3211[0m [38;5;124;03m    """[39;00m
[0;32m-> 3212[0m     [38;5;28;01mreturn[39;00m [38;5;28;43mself[39;49m[38;5;241;43m.[39;49m[43m_bind[49m[43m([49m[43margs[49m[43m,[49m[43m [49m[43mkwargs[49m[43m)[49m

File [0;32m~/miniconda3/lib/python3.11/inspect.py:3201[0m, in [0;36mSignature._bind[0;34m(self, args, kwargs, partial)[0m
[1;32m   3199[0m         arguments[kwargs_param[38;5;241m.[39mname] [38;5;241m=[39m kwargs
[1;32m   3200[0m     [38;5;28;01melse[39;00m:
[0;32m-> 3201[0m         [38;5;28;01mraise[39;00m [38;5;167;01mTypeError[39;00m(
[1;32m   3202[0m             [38;5;124m'[39m[38;5;124mgot an unexpected keyword argument [39m[38;5;132;01m{arg!r}[39;00m[38;5;124m'[39m[38;5;241m.[39mformat(
[1;32m   3203[0m                 arg[38;5;241m=[39m[38;5;28mnext[39m([38;5;28miter[39m(kwargs))))
[1;32m   3205[0m [38;5;28;01mreturn[39;00m [38;5;28mself[39m[38;5;241m.[39m_bound_arguments_cls([38;5;28mself[39m, arguments)

[0;31mTypeError[0m: got an unexpected keyword argument 'squared'

