Traceback (most recent call last):
  File "/home/nelo/miniconda3/lib/python3.11/site-packages/jupyter_cache/executors/utils.py", line 58, in single_nb_execution
    executenb(
  File "/home/nelo/miniconda3/lib/python3.11/site-packages/nbclient/client.py", line 1305, in execute
    return NotebookClient(nb=nb, resources=resources, km=km, **kwargs).execute()
           ^^^^^^^^^^^^^^^^^^^^^^^^^^^^^^^^^^^^^^^^^^^^^^^^^^^^^^^^^^^^^^^^^^^^^
  File "/home/nelo/miniconda3/lib/python3.11/site-packages/jupyter_core/utils/__init__.py", line 166, in wrapped
    return loop.run_until_complete(inner)
           ^^^^^^^^^^^^^^^^^^^^^^^^^^^^^^
  File "/home/nelo/miniconda3/lib/python3.11/asyncio/base_events.py", line 653, in run_until_complete
    return future.result()
           ^^^^^^^^^^^^^^^
  File "/home/nelo/miniconda3/lib/python3.11/site-packages/nbclient/client.py", line 705, in async_execute
    await self.async_execute_cell(
  File "/home/nelo/miniconda3/lib/python3.11/site-packages/nbclient/client.py", line 1058, in async_execute_cell
    await self._check_raise_for_error(cell, cell_index, exec_reply)
  File "/home/nelo/miniconda3/lib/python3.11/site-packages/nbclient/client.py", line 914, in _check_raise_for_error
    raise CellExecutionError.from_cell_and_msg(cell, exec_reply_content)
nbclient.exceptions.CellExecutionError: An error occurred while executing the following cell:
------------------
stacked_df = df.set_index(['Fecha', 'Categor√≠a', 'Tipo']).stack()

stacked_df
------------------


[0;31m---------------------------------------------------------------------------[0m
[0;31mKeyError[0m                                  Traceback (most recent call last)
[0;32m/tmp/ipykernel_16422/2269271074.py[0m in [0;36m?[0;34m()[0m
[0;32m----> 1[0;31m [0mstacked_df[0m [0;34m=[0m [0mdf[0m[0;34m.[0m[0mset_index[0m[0;34m([0m[0;34m[[0m[0;34m'Fecha'[0m[0;34m,[0m [0;34m'Categor√≠a'[0m[0;34m,[0m [0;34m'Tipo'[0m[0;34m][0m[0;34m)[0m[0;34m.[0m[0mstack[0m[0;34m([0m[0;34m)[0m[0;34m[0m[0;34m[0m[0m
[0m[1;32m      2[0m [0;34m[0m[0m
[1;32m      3[0m [0mstacked_df[0m[0;34m[0m[0;34m[0m[0m

[0;32m~/miniconda3/lib/python3.11/site-packages/pandas/core/frame.py[0m in [0;36m?[0;34m(self, keys, drop, append, inplace, verify_integrity)[0m
[1;32m   5869[0m                     [0;32mif[0m [0;32mnot[0m [0mfound[0m[0;34m:[0m[0;34m[0m[0;34m[0m[0m
[1;32m   5870[0m                         [0mmissing[0m[0;34m.[0m[0mappend[0m[0;34m([0m[0mcol[0m[0;34m)[0m[0;34m[0m[0;34m[0m[0m
[1;32m   5871[0m [0;34m[0m[0m
[1;32m   5872[0m         [0;32mif[0m [0mmissing[0m[0;34m:[0m[0;34m[0m[0;34m[0m[0m
[0;32m-> 5873[0;31m             [0;32mraise[0m [0mKeyError[0m[0;34m([0m[0;34mf"None of {missing} are in the columns"[0m[0;34m)[0m[0;34m[0m[0;34m[0m[0m
[0m[1;32m   5874[0m [0;34m[0m[0m
[1;32m   5875[0m         [0;32mif[0m [0minplace[0m[0;34m:[0m[0;34m[0m[0;34m[0m[0m
[1;32m   5876[0m             [0mframe[0m [0;34m=[0m [0mself[0m[0;34m[0m[0;34m[0m[0m

[0;31mKeyError[0m: "None of ['Categor√≠a'] are in the columns"

